Workbook

Sheet 5 Yr Proforma
E3: Location | F3: 114-138 E North Ave
E4: Rentable SQ FT's | F4: ='Rent Roll'!C9 -> 30704
E5: Price/SQF | F5: =F7/F4 -> 93.636008
E6: Tenants # | F6: 8
E7: Purchase Price | F7: 2875000 | G7: =100% -> 1
E8: Bank Loan | F8: =G8*F7 -> 2012500 | G8: 0.7
E9: Down Payment | F9: =F7-F8 -> 862500 | G9: =F9/F7 -> 0.3
E10: Closing Costs | F10: 37500 | G10: =F10/F7 -> 0.013043478
E11: Working Capital | F11: 260000 | G11: =F11/F7 -> 0.090434783
E12: Total Cash to Close | F12: =SUM(F9:F11) -> 1160000 | G12: =G7+G10 -> 1.0130435
E13: Bank Loan | F13: 0.065
E14: Term | F14: 25
E17: INCOME | G17: Y1 (Current) | H17: Y2 | I17: Y3 | J17: Y4 | K17: Y5
E19: Base Rent | G19: ='Rent Roll'!D9 -> 283204.04 | H19: ='Rent Roll'!L9 -> 287955.4 | I19: ='Rent Roll'!M9 -> 292737.28 | J19: ='Rent Roll'!N9 -> 299890.92 | K19: ='Rent Roll'!O9 -> 304281.78
E20: CAM | G20: =2.79*F4 -> 85664.16 | H20: =1.68*F4 -> 51582.72 | I20: =H20*1.03 -> 53130.202 | J20: =I20*1.03 -> 54724.108 | K20: =J20*1.03 -> 56365.831
E21: Tax | H21: =2.61*F4 -> 80137.44 | I21: =H21*1.03 -> 82541.563 | J21: =H21 -> 80137.44 | K21: =H21 -> 80137.44
E22: Insurance | H22: =0.39*F4 -> 11974.56 | I22: =H22*1.03 -> 12333.797 | J22: =I22*1.03 -> 12703.811 | K22: =J22*1.03 -> 13084.925
E24: Total Income | G24: =SUM(G19:G22) -> 368868.2 | H24: =SUM(H19:H23) -> 431650.12 | I24: =SUM(I19:I23) -> 440742.84 | J24: =SUM(J19:J22) -> 447456.27 | K24: =SUM(K19:K22) -> 453869.97
E26: General Vacancy | F26: 0.05 | G26: =G24*$F$26*-1 -> -18443.41 | H26: =H24*$F$26*-1 -> -21582.506 | I26: =I24*$F$26*-1 -> -22037.142 | J26: =J24*$F$26*-1 -> -22372.814 | K26: =K24*$F$26*-1 -> -22693.499
E28: Effective Gross Income | G28: =G24+G26 -> 350424.79 | H28: =H24+H26 -> 410067.61 | I28: =I24+I26 -> 418705.7 | J28: =J24+J26 -> 425083.46 | K28: =K24+K26 -> 431176.47
E30: EXPENSES
E32: General & Administrative | G32: 1000 | H32: 1000 | I32: 1000 | J32: 1000 | K32: 1000
E33: Advertising | G33: 1200 | H33: 1200 | I33: 1200 | J33: 1200 | K33: 1200
E34: Property Management (5%) | G34: =G28*0.05 -> 17521.239 | H34: =H28*0.05 -> 20503.381 | I34: =I28*0.05 -> 20935.285 | J34: =J28*0.05 -> 21254.173 | K34: =K28*0.05 -> 21558.824
E35: Asset Management (2%) | G35: =G28*0.02 -> 7008.4958 | H35: =H28*0.02 -> 8201.3523 | I35: =I28*0.02 -> 8374.114 | J35: =J28*0.02 -> 8501.6692 | K35: =K28*0.02 -> 8623.5294
B36: CAM Charges | C36: =G41+G42+G38+G39+G40+G34 -> 46721.24 | D36: =H41+H42+H38+H39+H40+H34 -> 50579.381 | E36: RE Taxes | G36: 26120 | H36: 80233 | I36: =H36*1.03 -> 82639.99 | J36: =I36*1.03 -> 85119.19 | K36: =J36*1.03 -> 87672.765
B37: CAM PSF | C37: =C36/F4 -> 1.5216662 | D37: =D36/F4 -> 1.6473222 | E37: Insurance | G37: 12000 | H37: =G37*1.03 -> 12360 | I37: =H37*1.03 -> 12730.8 | J37: =I37*1.03 -> 13112.724 | K37: =J37*1.03 -> 13506.106
B38: Taxes | C38: =G36 -> 26120 | D38: =H36 -> 80233 | E38: Waste | G38: =350*12 -> 4200 | H38: =G38*1.03 -> 4326 | I38: =H38*1.03 -> 4455.78 | J38: =I38*1.03 -> 4589.4534 | K38: =J38*1.03 -> 4727.137
B39: Taxes PSF | C39: =C38/F4 -> 0.85070349 | D39: =D38/F4 -> 2.6131123 | E39: Electricity and Gas | G39: 0 | H39: 0 | I39: 0 | J39: 0 | K39: 0
E40: Water & Sewer | G40: 0 | H40: 0 | I40: 0 | J40: 0 | K40: 0
B41: Insurance | C41: =G37 -> 12000 | E41: Landscape & Snow | G41: 15000 | H41: =G41*1.03 -> 15450 | I41: =H41*1.03 -> 15913.5 | J41: =I41*1.03 -> 16390.905 | K41: =J41*1.03 -> 16882.632
B42: Insurance PSF | C42: =C41/F4 -> 0.39082856 | D42: =C42*1.03 -> 0.40255341 | E42: Repairs / Maintenance | G42: 10000 | H42: =G42*1.03 -> 10300 | I42: =H42*1.03 -> 10609 | J42: =I42*1.03 -> 10927.27 | K42: =J42*1.03 -> 11255.088
B44: Total NNN | C44: =C37+C39+C42 -> 2.7631983 | D44: =D42+D39+D37 -> 4.6629879
E45: Total Expenses | G45: =SUM(G32:G43) -> 94049.735 | H45: =SUM(H32:H43) -> 153573.73 | I45: =SUM(I32:I43) -> 157858.47 | J45: =SUM(J32:J43) -> 162095.38 | K45: =SUM(K32:K43) -> 166426.08
E47: NOI | G47: =G28-G45 -> 256375.05 | H47: =H28-H45 -> 256493.88 | I47: =I28-I45 -> 260847.23 | J47: =J28-J45 -> 262988.08 | K47: =K28-K45 -> 264750.39
E49: Bank Debt Service | G49: =PMT(F13,F14,F8,0) -> -164987.73 | H49: =G49 -> -164987.73 | I49: =H49 -> -164987.73 | J49: =I49 -> -164987.73 | K49: =J49 -> -164987.73
E51: Cash Flow | G51: =SUM(G47:G49) -> 91387.324 | H51: =SUM(H47:H49) -> 91506.15 | I51: =SUM(I47:I49) -> 95859.5 | J51: =SUM(J47:J49) -> 98000.345 | K51: =SUM(K47:K49) -> 99762.66
E54: CAP % | G54: =G47/(F7+F10) -> 0.08802577 | H54: =H47/($F$7+$F$10) -> 0.088066569 | I54: =I47/($F$7+$F$10) -> 0.089561281 | J54: =J47/($F$7+$F$10) -> 0.090296335 | K54: =K47/($F$7+$F$10) -> 0.090901422
E55: CASH ON CASH % | G55: =G51/($F$12) -> 0.078782176 | H55: =H51/($F$12) -> 0.078884612 | I55: =I51/($F$12) -> 0.0826375 | J55: =J51/($F$12) -> 0.084483056 | K55: =K51/($F$12) -> 0.086002293
E56: DSCR | G56: =-G47/G49 -> 1.5539038 | H56: =-H47/H49 -> 1.554624 | I56: =-I47/I49 -> 1.5810099 | J56: =-J47/J49 -> 1.5939857 | K56: =-K47/K49 -> 1.6046671
...

Sheet Rent Roll
A1: Twin Oaks Shopping Center - 118-138 E North Ave Belton, MO
A2: Unit | B2: Tenant | C2: SF | D2: Base Rent | E2: Rent PSF | F2: Annual NNN Charges | G2: NNN PSF | H2: Annual | I2: Monthly Rent | J2: Lease Start | K2: Lease End | L2: Yr 1 | M2: Y2 | N2: Y3 | O2: Y4 | P2: Y5 | Q2: Notes
A3: 138-138A | B3: Napa | C3: 9152 | D3: 57200 | E3: =D3/C3 -> 6.25 | F3: 28688.88 | G3: =F3/C3 -> 3.1347115 | H3: =D3+F3 -> 85888.88 | I3: =H3/12 -> 7157.4067 | J3: 44562 | K3: 48213 | L3: =(E3+0.25)*C3 -> 59488 | M3: =L3 -> 59488 | N3: =(E3+0.25+0.25)*C3 -> 61776 | O3: =(E3+0.25+0.25)*C3 -> 61776 | P3: =(E3+0.25+0.25+0.25)*C3 -> 64064 | Q3: $0.25/SF increases every 2 years. Next increase 1/1/2026 ($6.25/SF).
A4: 134-136 | B4: Iron Gates Gym | C4: 12000 | D4: =8916.67*12 -> 107000.04 | E4: =D4/(C4) -> 8.91667 | F4: 25077.72 | G4: =F4/C4 -> 2.08981 | H4: =D4+F4 -> 132077.76 | I4: =H4/12 -> 11006.48 | J4: 45901 | K4: 47817 | L4: =9083.34*12 -> 109000.08 | M4: =9250*12 -> 111000 | N4: =9416.67*12 -> 113000.04 | O4: =9583.34*12 -> 115000.08 | P4: =O4*1.03 -> 118450.08 | Q4: Lease amounts through 2030 and then a 3% increase
A5: 128 | B5: Barber | C5: 1200 | D5: 15444 | E5: =D5/C5 -> 12.87 | F5: 3756 | G5: =F5/C5 -> 3.13 | H5: =D5+F5 -> 19200 | I5: =H5/12 -> 1600 | J5: 46113 | K5: 47208 | L5: =1325.61*12 -> 15907.32 | M5: =1365.38*12 -> 16384.56 | N5: =M5*1.03 -> 16876.097 | O5: =N5*1.03 -> 17382.38 | P5: =O5*1.03 -> 17903.851 | Q5: Lease amounts through 2028 and then 3% increase
A6: 124 | B6: Quinn's Laundry | C6: 2376 | D6: 26730 | E6: =D6/C6 -> 11.25 | F6: 7448.04 | G6: =F6/C6 -> 3.134697 | H6: =D6+F6 -> 34178.04 | I6: =H6/12 -> 2848.17 | J6: 40909 | K6: 47848 | L6: =E6*C6 -> 26730 | M6: =D6 -> 26730 | N6: =D6 -> 26730 | O6: =D6 -> 26730 | P6: =O6*1.03 -> 27531.9 | Q6: Lease amounts through 2030 and then 3% increase
A7: 120-122 | B7: Boost Mobile | C7: 1776 | D7: 23976 | E7: =D7/C7 -> 13.5 | F7: 5567.16 | G7: =F7/C7 -> 3.1346622 | H7: =D7+F7 -> 29543.16 | I7: =H7/12 -> 2461.93 | J7: 44835 | K7: 47118 | L7: =E7*C7 -> 23976 | M7: =L7*1.03 -> 24695.28 | N7: =M7*1.03 -> 25436.138 | O7: =N7*1.03 -> 26199.223 | P7: =O7*1.03 -> 26985.199 | Q7: $13.11/SF in 2026, and 3% increase thereafter
A8: 114-118 | B8: Smoke Shop | C8: 4200 | D8: 52854 | E8: =D8/C8 -> 12.584286 | F8: 13146 | G8: =F8/C8 -> 3.13 | H8: =D8+F8 -> 66000 | I8: =H8/12 -> 5500 | J8: 46235 | K8: 47422 | L8: =D8 -> 52854 | M8: =54439.44 -> 54439.44 | N8: 56072.64 | O8: =N8*1.02 -> 57194.093 | P8: =O8*1.02 -> 58337.975 | Q8: 2% annual increase after lease term ends
B9: TOTALS | C9: =SUM(C3:C8) -> 30704 | D9: =SUM(D3:D8) -> 283204.04 | F9: =SUM(F3:F8) -> 83683.8 | G9: =F9/C9 -> 2.7255016 | H9: =SUM(H3:H8) -> 366887.84 | I9: =SUM(I3:I8) -> 30573.987 | L9: =SUM(L3:L8) -> 287955.4 | M9: =SUM(M3:M8) -> 292737.28 | N9: =SUM(N3:N8) -> 299890.92 | O9: =SUM(O3:O8) -> 304281.78 | P9: =SUM(P3:P8) -> 313273.01
