Workbook

Sheet Proforma
C2: Location | D2: 1806-1856 N Pine Island Rd - Plantation
C3: $/PSQF | D3: =D6/D4 -> 307.94312
C4: Rentable SQ FT's | D4: ='Current Rent Roll'!C17 -> 11041
C5: Tenants # | D5: 11
C6: Purchase Price | D6: 3400000 | E6: =100% -> 1
C7: Seller Carry Loan | D7: =D6-D8 -> 2200000 | E7: =D7/D6 -> 0.64705882
C8: Down Payment | D8: 1200000 | E8: =D8/D6 -> 0.35294118
C9: Closing Costs | D9: 40000 | E9: =D9/D6 -> 0.011764706
C10: Acquisition Fee | D10: =D6*E10 -> 68000 | E10: 0.02
C11: Working Capital | D11: 342000 | E11: =D11/D6 -> 0.10058824
C12: Total Cash to Close | D12: =SUM(D8:D11) -> 1650000 | E12: =E6+E9 -> 1.0117647
C13: Bank Loan I | D13: 0.055
C14: Terms | D14: I/O
C17: INCOME | E17: Yr 1 | F17: Yr 2 | G17: Yr 3 | H17: Yr 4 | I17: Yr 5 | J17: Yr 6 | K17: Yr 7 | L17: Yr 8 | M17: Yr 9 | N17: Yr 10
C19: Base Rent | E19: ='7 YR - Rent Roll'!F17 -> 265112 | F19: ='7 YR - Rent Roll'!G17 -> 271729.5 | G19: ='7 YR - Rent Roll'!H17 -> 285315.97 | H19: ='7 YR - Rent Roll'!I17 -> 299581.77 | I19: ='7 YR - Rent Roll'!J17 -> 314560.86 | J19: ='7 YR - Rent Roll'!K17 -> 330288.91 | K19: ='7 YR - Rent Roll'!L17 -> 346803.35 | L19: ='7 YR - Rent Roll'!M17 -> 364143.52 | ... P19: ='7 YR - Rent Roll'!Q17
C20: NNN Reimbursements | E20: =0.5*8.74*D4 -> 48249.17 | F20: 118000 | G20: 122000 | H20: =1.03*G20 -> 125660 | I20: =1.03*H20 -> 129429.8 | J20: =1.03*I20 -> 133312.69 | K20: =1.03*J20 -> 137312.07 | L20: =1.03*K20 -> 141431.44 | M20: =1.03*L20 -> 145674.38 | N20: =1.03*M20 -> 150044.61
C22: Total Income | E22: =SUM(E19:E20) -> 313361.17 | F22: =SUM(F19:F20) -> 389729.5 | G22: =SUM(G19:G20) -> 407315.97 | H22: =SUM(H19:H20) -> 425241.77 | I22: =SUM(I19:I20) -> 443990.66 | J22: =SUM(J19:J20) -> 463601.6 | K22: =SUM(K19:K20) -> 484115.43 | L22: =SUM(L19:L20) -> 505574.96 | ... N22: =SUM(N19:N20) -> 551512.84
C24: General Vacancy | D24: 0.05 | E24: 0 | F24: =F22*$D$24*-1 -> -19486.475 | G24: =G22*$D$24*-1 -> -20365.799 | H24: =H22*$D$24*-1 -> -21262.089 | I24: =I22*$D$24*-1 -> -22199.533 | J24: =J22*$D$24*-1 -> -23180.08 | K24: =K22*$D$24*-1 -> -24205.771 | L24: =L22*$D$24*-1 -> -25278.748 | M24: =M22*$D$24*-1 -> -26401.254 | N24: =N22*$D$24*-1 -> -27575.642
C26: Effective Gross Income | E26: =E22+E24 -> 313361.17 | F26: =F22+F24 -> 370243.03 | G26: =G22+G24 -> 386950.18 | H26: =H22+H24 -> 403979.69 | I26: =I22+I24 -> 421791.13 | J26: =J22+J24 -> 440421.52 | K26: =K22+K24 -> 459909.65 | L26: =L22+L24 -> 480296.21 | ... N26: =N22+N24 -> 523937.2
C28: EXPENSES
C30: General & Administrative | E30: 1000 | F30: 1000 | G30: 1000 | H30: 1000 | I30: 1000 | J30: 1000 | K30: 1000 | L30: 1000 | M30: 1000 | N30: 1000
C31: Advertising | E31: 1200 | F31: 1200 | G31: 1200 | H31: 1200 | I31: 1200 | J31: 1200 | K31: 1200 | L31: 1200 | M31: 1200 | N31: 1200
C32: Property Management (5%) | E32: =E26*0.05 -> 15668.058 | F32: =F26*0.06 -> 22214.582 | G32: =G26*0.06 -> 23217.011 | H32: =H26*0.06 -> 24238.781 | I32: =I26*0.06 -> 25307.468 | J32: =J26*0.06 -> 26425.291 | K32: =K26*0.06 -> 27594.579 | L32: =L26*0.06 -> 28817.772 | M32: =M26*0.06 -> 30097.429 | N32: =N26*0.06 -> 31436.232
C33: Asset Management (2%) | E33: 6000 | F33: =F26*0.02 -> 7404.8605 | G33: =G26*0.02 -> 7739.0035 | H33: =H26*0.02 -> 8079.5937 | I33: =I26*0.02 -> 8435.8226 | J33: =J26*0.02 -> 8808.4304 | K33: =K26*0.02 -> 9198.1931 | L33: =L26*0.02 -> 9605.9242 | M33: =M26*0.02 -> 10032.476 | N33: =N26*0.02 -> 10478.744
C34: RE Taxes | E34: 38000 | F34: =0.015*D6 -> 51000 | G34: =F34*1.03 -> 52530 | H34: =G34*1.03 -> 54105.9 | I34: =H34*1.03 -> 55729.077 | J34: =I34*1.03 -> 57400.949 | K34: =J34*1.03 -> 59122.978 | L34: =K34*1.03 -> 60896.667 | M34: =L34*1.03 -> 62723.567 | N34: =M34*1.03 -> 64605.274
C35: Insurance | E35: =1.6*D4 -> 17665.6 | F35: =E35*1.03 -> 18195.568 | G35: =F35*1.03 -> 18741.435 | H35: =G35*1.03 -> 19303.678 | I35: =H35*1.03 -> 19882.788 | J35: =I35*1.03 -> 20479.272 | K35: =J35*1.03 -> 21093.65 | L35: =K35*1.03 -> 21726.46 | M35: =L35*1.03 -> 22378.254 | N35: =M35*1.03 -> 23049.601
C36: License & Permits | E36: 500 | F36: 500 | G36: 500 | H36: 500 | I36: 500 | J36: 500 | K36: 500 | L36: 500 | M36: 500 | N36: 500
C37: Waste & Utilities | E37: 2500 | F37: =E37*1.03 -> 2575 | G37: =F37*1.03 -> 2652.25 | H37: =G37*1.03 -> 2731.8175 | I37: =H37*1.03 -> 2813.772 | J37: =I37*1.03 -> 2898.1852 | K37: =J37*1.03 -> 2985.1307 | L37: =K37*1.03 -> 3074.6847 | M37: =L37*1.03 -> 3166.9252 | N37: =M37*1.03 -> 3261.933
C38: Landscape | E38: 5200 | F38: =E38*1.03 -> 5356 | G38: =F38*1.03 -> 5516.68 | H38: =G38*1.03 -> 5682.1804 | I38: =H38*1.03 -> 5852.6458 | J38: =I38*1.03 -> 6028.2252 | K38: =J38*1.03 -> 6209.0719 | L38: =K38*1.03 -> 6395.3441 | M38: =L38*1.03 -> 6587.2044 | N38: =M38*1.03 -> 6784.8206
C39: Pest Control | E39: 650 | F39: =E39*1.03 -> 669.5 | G39: =F39*1.03 -> 689.585 | H39: =G39*1.03 -> 710.27255 | I39: =H39*1.03 -> 731.58073 | J39: =I39*1.03 -> 753.52815 | K39: =J39*1.03 -> 776.13399 | L39: =K39*1.03 -> 799.41801 | M39: =L39*1.03 -> 823.40055 | N39: =M39*1.03 -> 848.10257
C40: Repair & Maintenance | F40: 10000 | G40: =F40*1.03 -> 10300 | H40: =G40*1.03 -> 10609 | I40: =H40*1.03 -> 10927.27 | J40: =I40*1.03 -> 11255.088 | K40: =J40*1.03 -> 11592.741 | L40: =K40*1.03 -> 11940.523 | M40: =L40*1.03 -> 12298.739 | N40: =M40*1.03 -> 12667.701
C42: Total Expenses | E42: =SUM(E30:E40) -> 88383.659 | F42: =SUM(F30:F40) -> 120115.51 | G42: =SUM(G30:G40) -> 124085.96 | H42: =SUM(H30:H40) -> 128161.22 | I42: =SUM(I30:I40) -> 132380.42 | J42: =SUM(J30:J40) -> 136748.97 | K42: =SUM(K30:K40) -> 141272.48 | L42: =SUM(L30:L40) -> 145956.79 | ... N42: =SUM(N30:N40) -> 155832.41
C44: NOI | E44: =E26-E42 -> 224977.51 | F44: =F26-F42 -> 250127.52 | G44: =G26-G42 -> 262864.21 | H44: =H26-H42 -> 275818.46 | I44: =I26-I42 -> 289410.71 | J44: =J26-J42 -> 303672.55 | K44: =K26-K42 -> 318637.18 | L44: =L26-L42 -> 334339.41 | ... N44: =N26-N42 -> 368104.79
C46: Bank Debt Service | E46: =-$D$13*$D$7 -> -121000 | F46: =-$D$13*$D$7 -> -121000 | G46: =-$D$13*$D$7 -> -121000 | H46: =-$D$13*$D$7 -> -121000 | I46: =-$D$13*$D$7 -> -121000 | J46: =-$D$13*$D$7 -> -121000 | K46: =-$D$13*$D$7 -> -121000 | L46: =-$D$13*$D$7 -> -121000 | ... N46: =-$D$13*$D$7 -> -121000
C48: Cash Flow | E48: =SUM(E44:E46) -> 103977.51 | F48: =SUM(F44:F46) -> 129127.51 | G48: =SUM(G44:G46) -> 141864.21 | H48: =SUM(H44:H46) -> 154818.46 | I48: =SUM(I44:I46) -> 168410.7 | J48: =SUM(J44:J46) -> 182672.55 | K48: =SUM(K44:K46) -> 197637.18 | L48: =SUM(L44:L46) -> 213339.41 | ... N48: =SUM(N44:N46) -> 247104.79
C50: CAP % | E50: =E44/(D6+D9) -> 0.065400439 | F50: =F44/($D$6+$D$9) -> 0.072711487 | G50: =G44/($D$6+$D$9) -> 0.076414015 | H50: =H44/($D$6+$D$9) -> 0.080179785 | I50: =I44/($D$6+$D$9) -> 0.084131019 | J50: =J44/($D$6+$D$9) -> 0.088276904 | K50: =K44/($D$6+$D$9) -> 0.092627086 | L50: =L44/($D$6+$D$9) -> 0.09719169 | M50: =M44/($D$6+$D$9) -> 0.10198134 | N50: =N44/($D$6+$D$9) -> 0.10700721
C51: CASH ON CASH % | E51: =E48/($D$12) -> 0.063016674 | F51: =F48/($D$12) -> 0.0782591 | G51: =G48/($D$12) -> 0.08597831 | H51: =H48/($D$12) -> 0.093829371 | I51: =I48/($D$12) -> 0.10206709 | J51: =J48/($D$12) -> 0.11071064 | K51: =K48/($D$12) -> 0.11978011 | L51: =L48/($D$12) -> 0.12929661 | ... N51: =N48/($D$12) -> 0.14976048
C52: DSCR | E52: =-E44/E46 -> 1.8593183 | F52: =-F44/F46 -> 2.0671695 | G52: =-G44/G46 -> 2.1724315 | H52: =-H44/H46 -> 2.2794914 | I52: =-I44/I46 -> 2.391824 | J52: =-J44/J46 -> 2.5096905 | K52: =-K44/K46 -> 2.6333651 | L52: =-L44/L46 -> 2.7631357 | ... N52: =-N44/N46 -> 3.0421884
C54: LP Preferred Return | D54: =-D12 -> -1650000 | E54: =E48 -> 103977.51 | F54: =F48 -> 129127.51 | G54: =G48 -> 141864.21 | H54: =115500+9502 -> 125002 | I54: =(D12*0.07) -> 115500 | J54: =(D12*0.07) -> 115500 | K54: =($D$12*0.07) -> 115500 | L54: =($D$12*0.07) -> 115500 | M54: =($D$12*0.07) -> 115500 | N54: =($D$12*0.07) -> 115500
C55: LP Waterfall | E55: 0 | F55: =(F48-F54)/2 -> 0 | G55: =(G48-G54)/2 -> 0 | H55: =(H48-H54)/2 -> 14908.231 | I55: =(I48-I54)/2 -> 26455.352 | J55: =(J48-J54)/2 -> 33586.275 | K55: =(K48-K54)/2 -> 41068.588 | L55: =(L48-L54)/2 -> 48919.707 | M55: =(M48-M54)/2 -> 57157.913 | N55: =(N48-N54)/2 -> 65802.395
...

Sheet 7 YR - Rent Roll
A1: SELMED INVESTMENT GROUP LLC
A2: Rent Roll
A3: Rent includes Electricity, Water and Common Area
A5: Unit | B5: Tenant | C5: SF | D5: Price/SF | E5: Monthly Rent | F5: Yr 1 | G5: Yr 2 | H5: Yr 3 | I5: Yr 4 | J5: Yr 5 | K5: Yr 6 | L5: Yr 7 | M5: Yr 8 | N5: Yr 9 | O5: Yr 10
A6: 1820 | B6: 954 Spot LLC | C6: 952 | D6: 21.3 | E6: 1689.8 | F6: 20277.6 | G6: =$C$20*C6 -> 23324 | H6: =G6*1.05 -> 24490.2 | I6: =H6*1.05 -> 25714.71 | J6: =I6*1.05 -> 27000.446 | K6: =J6*1.05 -> 28350.468 | L6: =K6*1.05 -> 29767.991 | M6: =L6*1.05 -> 31256.391 | N6: =M6*1.05 -> 32819.21 | O6: =N6*1.05 -> 34460.171
A7: 1836 | B7: America Enroll Insurance Advisors | C7: 750 | D7: 21.91 | E7: 1369.19 | F7: 16430.28 | G7: =$C$20*C7 -> 18375 | H7: =G7*1.05 -> 19293.75 | I7: =H7*1.05 -> 20258.438 | J7: =I7*1.05 -> 21271.359 | K7: =J7*1.05 -> 22334.927 | L7: =K7*1.05 -> 23451.674 | M7: =L7*1.05 -> 24624.257 | N7: =M7*1.05 -> 25855.47 | O7: =N7*1.05 -> 27148.244
A8: 1830 | B8: Family Therapy Providers | C8: 789 | D8: 23.46 | E8: 1542.75 | F8: 18513 | G8: =$C$20*C8 -> 19330.5 | H8: =G8*1.05 -> 20297.025 | I8: =H8*1.05 -> 21311.876 | J8: =I8*1.05 -> 22377.47 | K8: =J8*1.05 -> 23496.344 | L8: =K8*1.05 -> 24671.161 | M8: =L8*1.05 -> 25904.719 | N8: =M8*1.05 -> 27199.955 | O8: =N8*1.05 -> 28559.952
A9: 1840 | B9: HMG Clean Out Inc | C9: 1000 | D9: 6 | E9: 500 | F9: =C20*C9 -> 24500 | G9: =F9*1.05 -> 25725 | H9: =G9*1.05 -> 27011.25 | I9: =H9*1.05 -> 28361.812 | J9: =I9*1.05 -> 29779.903 | K9: =J9*1.05 -> 31268.898 | L9: =K9*1.05 -> 32832.343 | M9: =L9*1.05 -> 34473.96 | N9: =M9*1.05 -> 36197.658 | O9: =N9*1.05 -> 38007.541
A10: 1806 | B10: PMC Plantation LLC | C10: 3150 | D10: 28.83 | E10: 7569.17 | F10: 90830.04 | G10: =$C$20*C10 -> 77175 | H10: =G10*1.05 -> 81033.75 | I10: =H10*1.05 -> 85085.438 | J10: =I10*1.05 -> 89339.709 | K10: =J10*1.05 -> 93806.695 | L10: =K10*1.05 -> 98497.03 | M10: =L10*1.05 -> 103421.88 | N10: =M10*1.05 -> 108592.98 | O10: =N10*1.05 -> 114022.62
A11: 1856 | B11: Soothing Oasis Massage LLC | C11: 1009 | D11: 21.84 | E11: 1836.11 | F11: 22033.32 | G11: =$C$20*C11 -> 24720.5 | H11: =G11*1.05 -> 25956.525 | I11: =H11*1.05 -> 27254.351 | J11: =I11*1.05 -> 28617.069 | K11: =J11*1.05 -> 30047.922 | L11: =K11*1.05 -> 31550.318 | M11: =L11*1.05 -> 33127.834 | N11: =M11*1.05 -> 34784.226 | O11: =N11*1.05 -> 36523.437
A12: 1846 | B12: US Rx Distribution LLC | C12: 1200 | D12: 26.69 | E12: 2669 | F12: 32028 | G12: =$C$20*C12 -> 29400 | H12: =G12*1.05 -> 30870 | I12: =H12*1.05 -> 32413.5 | J12: =I12*1.05 -> 34034.175 | K12: =J12*1.05 -> 35735.884 | L12: =K12*1.05 -> 37522.678 | M12: =L12*1.05 -> 39398.812 | N12: =M12*1.05 -> 41368.752 | O12: =N12*1.05 -> 43437.19
A13: 1834 | B13: Home Makers Companions | C13: 550 | D13: 16.19 | E13: 1051.88 | F13: 12622.56 | G13: =$C$20*C13 -> 13475 | H13: =G13*1.05 -> 14148.75 | I13: =H13*1.05 -> 14856.188 | J13: =I13*1.05 -> 15598.997 | K13: =J13*1.05 -> 16378.947 | L13: =K13*1.05 -> 17197.894 | M13: =L13*1.05 -> 18057.789 | N13: =M13*1.05 -> 18960.678 | O13: =N13*1.05 -> 19908.712
A14: 1850 | B14: LeMacks Salon | C14: 1041 | D14: 19.86 | E14: 1723.1 | F14: 20677.2 | G14: =$C$20*C14 -> 25504.5 | H14: =G14*1.05 -> 26779.725 | I14: =H14*1.05 -> 28118.711 | J14: =I14*1.05 -> 29524.647 | K14: =J14*1.05 -> 31000.879 | L14: =K14*1.05 -> 32550.923 | M14: =L14*1.05 -> 34178.469 | N14: =M14*1.05 -> 35887.393 | O14: =N14*1.05 -> 37681.762
A15: 1816 | B15: Vacant | C15: 300 | D15: 24 | E15: 381.25 | F15: =D15*C15/2 -> 3600 | G15: =$C$20*C15 -> 7350 | H15: =G15*1.05 -> 7717.5 | I15: =H15*1.05 -> 8103.375 | J15: =I15*1.05 -> 8508.5438 | K15: =J15*1.05 -> 8933.9709 | L15: =K15*1.05 -> 9380.6695 | M15: =L15*1.05 -> 9849.703 | N15: =M15*1.05 -> 10342.188 | O15: =N15*1.05 -> 10859.298
A16: 1818 | B16: Leasing Office - Vacant | C16: 300 | D16: 24 | E16: 381.25 | F16: =D16*C16/2 -> 3600 | G16: =$C$20*C16 -> 7350 | H16: =G16*1.05 -> 7717.5 | I16: =H16*1.05 -> 8103.375 | J16: =I16*1.05 -> 8508.5438 | K16: =J16*1.05 -> 8933.9709 | L16: =K16*1.05 -> 9380.6695 | M16: =L16*1.05 -> 9849.703 | N16: =M16*1.05 -> 10342.188 | O16: =N16*1.05 -> 10859.298
A17: Totals | C17: =SUM(C6:C16) -> 11041 | E17: =SUM(E6:E16) -> 20713.5 | F17: =SUM(F6:F16) -> 265112 | G17: =SUM(G6:G16) -> 271729.5 | H17: =SUM(H6:H16) -> 285315.97 | I17: =SUM(I6:I16) -> 299581.77 | J17: =SUM(J6:J16) -> 314560.86 | K17: =SUM(K6:K16) -> 330288.91 | L17: =SUM(L6:L16) -> 346803.35 | ... O17: =SUM(O6:O16) -> 401468.23
F18: =F17/Proforma!$D$4 -> 24.011593 | G18: =G17/Proforma!$D$4 -> 24.61095 | H18: =H17/Proforma!$D$4 -> 25.841498 | I18: =I17/Proforma!$D$4 -> 27.133572 | J18: =J17/Proforma!$D$4 -> 28.490251 | K18: =K17/Proforma!$D$4 -> 29.914764 | L18: =L17/Proforma!$D$4 -> 31.410502
B20: Market Rent | C20: 24.5

Sheet Current Rent Roll
A1: SELMED INVESTMENT GROUP LLC
A2: Rent Roll
A3: Rent includes Electricity, Water and Common Area
A5: Unit | B5: Tenant | C5: SF | D5: Price/SF | E5: Annual Rent | F5: Monthly Rent | G5: Annual Adjust | H5: Lease Start | I5: Lease End | J5: Remarks
A6: 1820 | B6: 954 Spot LLC | C6: 952 | D6: 21.3 | E6: 20277.6 | F6: 1689.8 | H6: 8/17/2021 | I6: MTM
A7: 1836 | B7: America Enroll Insurance Advisors | C7: 750 | D7: 21.91 | E7: 16430.28 | F7: 1369.19 | H7: 1/7/2020 | I7: 1/31/2026
A8: 1830 | B8: Family Therapy Providers | C8: 789 | D8: 23.46 | E8: 18513 | F8: 1542.75 | H8: 6/13/2017 | I8: MTM
A9: 1840 | B9: HMG Clean Out Inc | C9: 1000 | D9: 6 | E9: 6000 | F9: 500 | G9: 3% | H9: 9/1/2024 | I9: 10/31/2025
A10: 1806 | B10: PMC Plantation LLC | C10: 3150 | D10: 28.83 | E10: 90830.04 | F10: 7569.17 | G10: 3% | H10: 4/27/2006 | I10: 4/30/2026 | J10: Extension
A11: 1856 | B11: Soothing Oasis Massage LLC | C11: 1009 | D11: 21.84 | E11: 22033.32 | F11: 1836.11 | G11: 3% | H11: 4/1/2010 | I11: 5/24/2026 | J11: Extension
A12: 1846 | B12: US Rx Distribution LLC | C12: 1200 | D12: 26.69 | E12: 32028 | F12: 2669 | G12: 3% | H12: 6/1/2022 | I12: 5/31/2026
A13: 1834 | B13: Home Makers Companions | C13: 550 | D13: 16.19 | E13: 12622.56 | F13: 1051.88 | G13: 3% | H13: 6/20/2017 | I13: MTM
A14: 1850 | B14: LeMacks Salon | C14: 1041 | D14: 19.86 | E14: 20677.2 | F14: 1723.1 | H14: 4/1/2019 | I14: MTM
A15: 1816 | B15: Vacant | C15: 300
A16: 1818 | B16: Leasing Office - Vacant | C16: 300
A17: Totals | C17: =SUM(C6:C16) -> 11041 | E17: =F17*12 -> 239412 | F17: =SUM(F6:F16) -> 19951
